<?xml version="1.0" ?>
<!-- =================================================================================== -->
<!-- |    This document was autogenerated by xacro from /usr/local/yanthra/share/robo_description/urdf/URDF | -->
<!-- |    EDITING THIS FILE BY HAND IS NOT RECOMMENDED                                 | -->
<!-- =================================================================================== -->
<robot name="yanthra_p8_prec_arm_01">
  <link name="base_link" />
  <link name="link2">
    <inertial>
      <origin rpy="0 0 0" xyz="0.00671738318110821 -1.39878117562109E-05 0.2202769758554" />
      <mass value="10.5303822457645" />
      <inertia ixx="2.19471739983396" ixy="2.80983690582654E-05" ixz="-0.0913179901889557" iyy="2.20641308598599" iyz="0.000194155490385104" izz="0.14796451182921" />
    </inertial>
    <visual>
      <origin rpy="0 0 0" xyz="0 0 0" />
      <geometry>
        <mesh filename="package://robo_description/meshes/link2.STL" />
      </geometry>
      <material name="">
        <color rgba="0.792156862745098 0.819607843137255 0.933333333333333 1" />
      </material>
    </visual>
    <collision>
      <origin rpy="0 0 0" xyz="0 0 0" />
      <geometry>
        <mesh filename="package://robo_description/meshes/link2.STL" />
      </geometry>
    </collision>
  </link>
  <joint name="base" type="fixed">
    <origin rpy="0 0 0" xyz="0 0 0" />
    <parent link="base_link" />
    <child link="link2" />
  </joint>
  <link name="link4">
    <inertial>
      <origin rpy="0 0 0" xyz="-0.0176408555693803 0.152790521657912 -3.83098668862436E-05" />
      <mass value="0.282499017152056" />
      <inertia ixx="0.00298330035697104" ixy="0.000394818490792966" ixz="-6.34474300730988E-07" iyy="0.0014039626895121" iyz="-1.97955549546787E-09" izz="0.00421178041660722" />
    </inertial>
    <visual>
      <origin rpy="0 0 0" xyz="0 0 0" />
      <geometry>
        <mesh filename="package://robo_description/meshes/link4.STL" />
      </geometry>
      <material name="">
        <color rgba="0.792156862745098 0.819607843137255 0.933333333333333 1" />
      </material>
    </visual>
    <collision>
      <origin rpy="0 0 0" xyz="0 0 0" />
      <geometry>
        <mesh filename="package://robo_description/meshes/link4.STL" />
      </geometry>
    </collision>
  </link>
  <joint name="joint4" type="revolute">
    <origin rpy="-1.5708 -7.4062E-14 -1.5745" xyz="0.2428 0 1.5212" />
    <parent link="link2" />
    <child link="link4" />
    <axis xyz="0 1 0" />
    <limit effort="0" lower="-2.618" upper="2.618" velocity="0" />
  </joint>
  <link name="link3">
    <inertial>
      <origin rpy="0 0 0" xyz="-0.00357584542379308 6.64118548501236E-05 0.00553295459478176" />
      <mass value="2.17956264938222" />
      <inertia ixx="0.0414316917809999" ixy="-0.000281615863153266" ixz="-0.000912975482692995" iyy="0.0376556663449139" iyz="0.00119419286492262" izz="0.0117798077279493" />
    </inertial>
    <visual>
      <origin rpy="0 0 0" xyz="0 0 0" />
      <geometry>
        <mesh filename="package://robo_description/meshes/link3.STL" />
      </geometry>
      <material name="">
        <color rgba="0.792156862745098 0.819607843137255 0.933333333333333 1" />
      </material>
    </visual>
    <collision>
      <origin rpy="0 0 0" xyz="0 0 0" />
      <geometry>
        <mesh filename="package://robo_description/meshes/link3.STL" />
      </geometry>
    </collision>
  </link>
  <joint name="joint3" type="revolute">
    <origin rpy="0.22839957 -0.01548624 0.43732779" xyz="58.40825319 25.46948143 -45.90503301" />
    <parent link="link4" />
    <child link="link3" />
    <axis xyz="-1 0 0" />
    <limit effort="0" lower="0" upper="1.5708" velocity="0" />
  </joint>
  <link name="link5">
    <inertial>
      <origin rpy="0 0 0" xyz="-4.44244915831504E-06 4.97452369918605E-06 0.00549697982686725" />
      <mass value="0.187819600198768" />
      <inertia ixx="0.00276866023394612" ixy="-2.52989833554357E-08" ixz="1.67678891723624E-07" iyy="0.00276626164643187" iyz="-1.96244360741618E-07" izz="6.18814668466856E-05" />
    </inertial>
    <visual>
      <origin rpy="0 0 0" xyz="0 0 0" />
      <geometry>
        <mesh filename="package://robo_description/meshes/link5.STL" />
      </geometry>
      <material name="">
        <color rgba="0.792156862745098 0.819607843137255 0.933333333333333 1" />
      </material>
    </visual>
    <collision>
      <origin rpy="0 0 0" xyz="0 0 0" />
      <geometry>
        <mesh filename="package://robo_description/meshes/link5.STL" />
      </geometry>
    </collision>
  </link>
  <joint name="joint5" type="prismatic">
    <origin rpy="1.8014E-16 -9.9356E-16 -1.3877E-15" xyz="0 0 0.1415" />
    <parent link="link3" />
    <child link="link5" />
    <axis xyz="0 0 1" />
    <limit effort="0" lower="0" upper="0.471" velocity="0" />
  </joint>
  <link name="link5_min">
    <inertial>
      <origin rpy="0 0 0" xyz="-4.442449158093E-06 4.9745236994081E-06 -0.195503020173131" />
      <mass value="0.18781960019877" />
      <inertia ixx="0.00276866023394617" ixy="-2.52989833553729E-08" ixz="1.67678891724306E-07" iyy="0.00276626164643192" iyz="-1.96244360744941E-07" izz="6.1881466846686E-05" />
    </inertial>
    <visual>
      <origin rpy="0 0 0" xyz="0 0 0" />
      <geometry>
        <mesh filename="package://robo_description/meshes/link5_min.STL" />
      </geometry>
      <material name="">
        <color rgba="0.792156862745098 0.819607843137255 0.933333333333333 1" />
      </material>
    </visual>
    <collision>
      <origin rpy="0 0 0" xyz="0 0 0" />
      <geometry>
        <mesh filename="package://robo_description/meshes/link5_min.STL" />
      </geometry>
    </collision>
  </link>
  <joint name="joint5_min" type="fixed">
    <origin rpy="2.1126E-16 -3.7297E-16 -1.3553E-20" xyz="0 0 0.201" />
    <parent link="link5" />
    <child link="link5_min" />
    <axis xyz="0 0 0" />
  </joint>
  <link name="link9">
    <inertial>
      <origin rpy="0 0 0" xyz="0.00595017700068134 -0.151862229846295 0.000805757206559399" />
      <mass value="0.0676325607171271" />
      <inertia ixx="0.00131283920363953" ixy="5.8437722215577E-05" ixz="9.18624590162929E-08" iyy="4.44215121275963E-05" iyz="-2.70331863513455E-06" izz="0.00135702805296492" />
    </inertial>
    <visual>
      <origin rpy="0 0 0" xyz="0 0 0" />
      <geometry>
        <mesh filename="package://robo_description/meshes/link9.STL" />
      </geometry>
      <material name="">
        <color rgba="0.792156862745098 0.819607843137255 0.933333333333333 1" />
      </material>
    </visual>
    <collision>
      <origin rpy="0 0 0" xyz="0 0 0" />
      <geometry>
        <mesh filename="package://robo_description/meshes/link9.STL" />
      </geometry>
    </collision>
  </link>
  <joint name="joint9" type="fixed">
    <origin rpy="-5.1264E-16 9.8272E-16 -3.3231E-16" xyz="-0.025 0.41425 0.201" />
    <parent link="link5" />
    <child link="link9" />
    <axis xyz="0 0 0" />
  </joint>
  <link name="link10">
    <inertial>
      <origin rpy="0 0 0" xyz="-0.000452102043834612 -0.00388398256530298 -0.0359428541627931" />
      <mass value="0.133278307803019" />
      <inertia ixx="0.000176111712333701" ixy="1.2906078645661E-06" ixz="-2.81456228892713E-06" iyy="0.00018043766397401" iyz="1.52348759517545E-05" izz="9.57545588895396E-05" />
    </inertial>
    <visual>
      <origin rpy="0 0 0" xyz="0 0 0" />
      <geometry>
        <mesh filename="package://robo_description/meshes/link10.STL" />
      </geometry>
      <material name="">
        <color rgba="0.792156862745098 0.819607843137255 0.933333333333333 1" />
      </material>
    </visual>
    <collision>
      <origin rpy="0 0 0" xyz="0 0 0" />
      <geometry>
        <mesh filename="package://robo_description/meshes/link10.STL" />
      </geometry>
    </collision>
  </link>
  <joint name="joint10" type="fixed">
    <origin rpy="-1.5287E-16 9.8315E-16 0.075241" xyz="0 0 0.29653" />
    <parent link="link5" />
    <child link="link10" />
    <axis xyz="0 0 0" />
  </joint>
  <link name="link6">
    <inertial>
      <origin rpy="0 0 0" xyz="0.0597797121085357 -0.00415947787772075 0.00396102337249675" />
      <mass value="0.11044935450504" />
      <inertia ixx="5.54064985415983E-05" ixy="1.51107175386632E-06" ixz="8.71007112212434E-06" iyy="0.000202454445144802" iyz="-1.95570852464242E-07" izz="0.000242414254783541" />
    </inertial>
    <visual>
      <origin rpy="0 0 0" xyz="0 0 0" />
      <geometry>
        <mesh filename="package://robo_description/meshes/link6.STL" />
      </geometry>
      <material name="">
        <color rgba="0.792156862745098 0.819607843137255 0.933333333333333 1" />
      </material>
    </visual>
    <collision>
      <origin rpy="0 0 0" xyz="0 0 0" />
      <geometry>
        <mesh filename="package://robo_description/meshes/link6.STL" />
      </geometry>
    </collision>
  </link>
  <joint name="joint6" type="fixed">
    <origin rpy="-0.49875645 -0.01883592 0.01427715" xyz="-0.02282017 0.06095069 0.00063775" />
    <parent link="link3" />
    <child link="link6" />
    <axis xyz="0 0 0" />
  </joint>
  <link name="link7">
    <inertial>
      <origin rpy="0 0 0" xyz="0.0238297121085362 0.00573332228764745 -0.00735587845542894" />
      <mass value="0.11044935450504" />
      <inertia ixx="5.54064985415981E-05" ixy="1.51107175386639E-06" ixz="8.71007112212417E-06" iyy="0.000202454445144801" iyz="-1.95570852464289E-07" izz="0.00024241425478354" />
    </inertial>
    <visual>
      <origin rpy="0 0 0" xyz="0 0 0" />
      <geometry>
        <mesh filename="package://robo_description/meshes/link7.STL" />
      </geometry>
      <material name="">
        <color rgba="0.792156862745098 0.819607843137255 0.933333333333333 1" />
      </material>
    </visual>
    <collision>
      <origin rpy="0 0 0" xyz="0 0 0" />
      <geometry>
        <mesh filename="package://robo_description/meshes/link7.STL" />
      </geometry>
    </collision>
  </link>
  <joint name="joint7" type="fixed">
    <origin rpy="7.7321E-17 4.3368E-19 0" xyz="0.03595 -0.0098928 0.011317" />
    <parent link="link6" />
    <child link="link7" />
    <axis xyz="0 0 0" />
  </joint>
  <link name="link8">
    <inertial>
      <origin rpy="0 0 0" xyz="0.00882971210853589 0.00573332228764789 -0.00735587845542833" />
      <mass value="0.11044935450504" />
      <inertia ixx="5.54064985415981E-05" ixy="1.51107175386635E-06" ixz="8.71007112212448E-06" iyy="0.000202454445144802" iyz="-1.95570852464174E-07" izz="0.000242414254783541" />
    </inertial>
    <visual>
      <origin rpy="0 0 0" xyz="0 0 0" />
      <geometry>
        <mesh filename="package://robo_description/meshes/link8.STL" />
      </geometry>
      <material name="">
        <color rgba="0.792156862745098 0.819607843137255 0.933333333333333 1" />
      </material>
    </visual>
    <collision>
      <origin rpy="0 0 0" xyz="0 0 0" />
      <geometry>
        <mesh filename="package://robo_description/meshes/link8.STL" />
      </geometry>
    </collision>
  </link>
  <joint name="joint8" type="fixed">
    <origin rpy="7.7321E-17 4.3368E-19 0" xyz="0.05095 -0.0098928 0.011317" />
    <parent link="link6" />
    <child link="link8" />
    <axis xyz="0 0 0" />
  </joint>
  <link name="camera_link">
    <visual>
      <origin rpy="0 0 0" xyz="0 0 0" />
      <geometry>
        <box size="0.001 0.001 0.001" />
      </geometry>
    </visual>
  </link>
  <joint name="camera_link_joint" type="fixed">
    <origin rpy="0 0 0" xyz="0 0 0" />
    <parent link="link7" />
    <child link="camera_link" />
  </joint>
  <link name="camera_color_frame">
    <visual>
      <origin rpy="0 0 0" xyz="0 0 0" />
      <geometry>
        <box size="0.001 0.001 0.001" />
      </geometry>
    </visual>
  </link>
  <joint name="camera_color_frame_joint" type="fixed">
    <origin rpy="0 0 0" xyz="0 0 0" />
    <parent link="camera_link" />
    <child link="camera_color_frame" />
  </joint>
  <link name="camera_color_optical_frame">
    <visual>
      <origin rpy="0 0 0" xyz="0 0 0" />
      <geometry>
        <box size="0.001 0.001 0.001" />
      </geometry>
    </visual>
  </link>
  <joint name="camera_color_optical_frame_joint" type="fixed">
    <origin rpy="0 0 0" xyz="0 0 0" />
    <parent link="camera_color_frame" />
    <child link="camera_color_optical_frame" />
  </joint>
  <link name="camera_depth_frame">
    <visual>
      <origin rpy="0 0 0" xyz="0 0 0" />
      <geometry>
        <box size="0.001 0.001 0.001" />
      </geometry>
    </visual>
  </link>
  <joint name="camera_depth_frame_joint" type="fixed">
    <origin rpy="0 0 0" xyz="0 0 0" />
    <parent link="camera_link" />
    <child link="camera_depth_frame" />
  </joint>
  <link name="camera_depth_optical_frame">
    <visual>
      <origin rpy="0 0 0" xyz="0 0 0" />
      <geometry>
        <box size="0.001 0.001 0.001" />
      </geometry>
    </visual>
  </link>
  <joint name="camera_depth_optical_frame_joint" type="fixed">
    <origin rpy="0 0 0" xyz="0 0 0" />
    <parent link="camera_depth_frame" />
    <child link="camera_depth_optical_frame" />
  </joint>
  <gazebo reference="stand">
    <material>Gazebo/Grey</material>
  </gazebo>
  <gazebo reference="link3">
    <material>Gazebo/Green</material>
  </gazebo>
  <gazebo reference="link4">
    <material>Gazebo/Red</material>
  </gazebo>
  <gazebo reference="link5">
    <material>Gazebo/Green</material>
  </gazebo>
  <gazebo reference="link9">
    <material>Gazebo/Red</material>
  </gazebo>
  <gazebo reference="link6">
    <material>Gazebo/White</material>
  </gazebo>
  <transmission name="tran1">
    <type>transmission_interface/SimpleTransmission</type>
    <joint name="joint3">
      <hardwareInterface>hardware_interface/PositionJointInterface</hardwareInterface>
    </joint>
    <actuator name="motor1">
      <hardwareInterface>hardware_interface/PositionJointInterface</hardwareInterface>
      <mechanicalReduction>1</mechanicalReduction>
    </actuator>
  </transmission>
  <transmission name="tran1">
    <type>transmission_interface/SimpleTransmission</type>
    <joint name="joint4">
      <hardwareInterface>hardware_interface/PositionJointInterface</hardwareInterface>
    </joint>
    <actuator name="motor1">
      <hardwareInterface>hardware_interface/PositionJointInterface</hardwareInterface>
      <mechanicalReduction>1</mechanicalReduction>
    </actuator>
  </transmission>
  <transmission name="tran1">
    <type>transmission_interface/SimpleTransmission</type>
    <joint name="joint5">
      <hardwareInterface>hardware_interface/PositionJointInterface</hardwareInterface>
    </joint>
    <actuator name="motor1">
      <hardwareInterface>hardware_interface/PositionJointInterface</hardwareInterface>
      <mechanicalReduction>1</mechanicalReduction>
    </actuator>
  </transmission>
  <gazebo>
    <plugin filename="libgazebo_ros_control.so" name="gazebo_ros_control">
      <robotNameSpace>/arm_controller</robotNameSpace>
    </plugin>
  </gazebo>
</robot>
